<robot name="UArm">

  <!-- Link 1 -->
  <link name="link1">
    <visual>
      <origin xyz="0 0 0" rpy="0 0 0"/>
      <geometry>
        <mesh filename="package://UArm_description/meshes/Base.stl" scale="0.001 0.001 0.001"/>
      </geometry>
    </visual>
  </link>

  <!-- Joint 1 -->
  <joint name="joint1" type="revolute">
    <parent link="link1"/>
    <child link="link2"/>
    <origin xyz="0 0 0.0095" rpy="0 0 0"/>
    <axis xyz="0 0 1"/>
    <limit lower="-3.14" upper="3.14" effort="1" velocity="1"/>
  </joint>

  <!-- Link 2 -->
  <link name="link2">
    <visual>
      <origin xyz="0 0 0" rpy="0 0 0"/>
      <geometry>
        <mesh filename="package://UArm_description/meshes/Link1.stl" scale="0.001 0.001 0.001"/>
      </geometry>
    </visual>
  </link>

  <!-- Joint 2 -->
  <joint name="joint2" type="revolute">
    <parent link="link2"/>
    <child link="link3"/>
    <origin xyz="0 -0.02 0.075" rpy="0 0 0"/>
    <axis xyz="0 1 0"/>
    <limit lower="-3.14" upper="3.14" effort="1" velocity="1"/>
  </joint>

  <!-- Link 3 -->
  <link name="link3">
    <visual>
      <origin xyz="0 0 0" rpy="0 0 0"/>
      <geometry>
        <mesh filename="package://UArm_description/meshes/Link2.stl" scale="0.001 0.001 0.001"/>
      </geometry>
    </visual>
  </link>

  <!-- Joint 3 -->
  <joint name="joint3" type="revolute">
    <parent link="link3"/>
    <child link="link4"/>
    <origin xyz="0 0.058 0.162" rpy="0 0 0"/>
    <axis xyz="1 0 0"/>
    <limit lower="-3.14" upper="3.14" effort="1" velocity="1"/>
  </joint>

  <!-- Link 4 -->
  <link name="link4">
    <visual>
      <origin xyz="0 0 0" rpy="0 0 0"/>
      <geometry>
        <mesh filename="package://UArm_description/meshes/Link3.stl" scale="0.001 0.001 0.001"/>
      </geometry>
    </visual>
  </link>

  <!-- Joint 4 -->
  <joint name="joint4" type="revolute">
    <parent link="link4"/>
    <child link="link5"/>
    <origin xyz="0 -0.21 -0.035" rpy="0 0 0"/>
    <axis xyz="0 1 0"/>
    <limit lower="-3.14" upper="3.14" effort="1" velocity="1"/>
  </joint>

  <!-- Link 5 -->
  <link name="link5">
    <visual>
      <origin xyz="0 0 0" rpy="0 0 0"/>
      <geometry>
        <mesh filename="package://UArm_description/meshes/Link4.stl" scale="0.001 0.001 0.001"/>
      </geometry>
    </visual>
  </link>

</robot>
