<robot name="UArm">

  <!-- Link 1 (Base) -->
  <link name="link1">
    <inertial>
      <origin xyz="0 0 0" rpy="0 0 0"/>
      <mass value="0.5"/>
      <inertia ixx="0.0001" iyy="0.0001" izz="0.0001" ixy="0" ixz="0" iyz="0"/>
    </inertial>
    <visual>
      <origin xyz="0 0 0" rpy="0 0 0"/>
      <geometry>
        <mesh filename="../meshes/Base.stl" scale="0.001 0.001 0.001"/>
      </geometry>
    </visual>
    <collision>
      <origin xyz="0 0 0" rpy="0 0 0"/>
      <geometry>
        <mesh filename="/meshes/Base.stl" scale="0.001 0.001 0.001"/>
      </geometry>
    </collision>
  </link>

  <!-- Link 2 -->
  <link name="link2">
    <inertial>
      <origin xyz="0 0 0" rpy="0 0 0"/>
      <mass value="0.3"/>
      <inertia ixx="0.00005" iyy="0.00005" izz="0.00005" ixy="0" ixz="0" iyz="0"/>
    </inertial>
    <visual>
      <origin xyz="0 0 0" rpy="0 0 0"/>
      <geometry>
        <mesh filename="../meshes/Link1.stl" scale="0.001 0.001 0.001"/>
      </geometry>
    </visual>
    <collision>
      <origin xyz="0 0 0" rpy="0 0 0"/>
      <geometry>
        <mesh filename="../meshes/Link1.stl" scale="0.001 0.001 0.001"/>
      </geometry>
    </collision>
  </link>

  <!-- Link 3 -->
  <link name="link3">
    <inertial>
      <origin xyz="0 0 0" rpy="0 0 0"/>
      <mass value="0.3"/>
      <inertia ixx="0.00005" iyy="0.00005" izz="0.00005" ixy="0" ixz="0" iyz="0"/>
    </inertial>
    <visual>
      <origin xyz="0 0 0" rpy="0 0 0"/>
      <geometry>
        <mesh filename="../meshes/Link2.stl" scale="0.001 0.001 0.001"/>
      </geometry>
    </visual>
    <collision>
      <origin xyz="0 0 0" rpy="0 0 0"/>
      <geometry>
        <mesh filename="../meshes/Link2.stl" scale="0.001 0.001 0.001"/>
      </geometry>
    </collision>
  </link>

  <!-- Link 4 -->
  <link name="link4">
    <inertial>
      <origin xyz="0 0 0" rpy="0 0 0"/>
      <mass value="0.2"/>
      <inertia ixx="0.00003" iyy="0.00003" izz="0.00003" ixy="0" ixz="0" iyz="0"/>
    </inertial>
    <visual>
      <origin xyz="0 0 0" rpy="0 0 0"/>
      <geometry>
        <mesh filename="../meshes/Link3.stl" scale="0.001 0.001 0.001"/>
      </geometry>
    </visual>
    <collision>
      <origin xyz="0 0 0" rpy="0 0 0"/>
      <geometry>
        <mesh filename="../meshes/Link3.stl" scale="0.001 0.001 0.001"/>
      </geometry>
    </collision>
  </link>


  <link name="link5">
    <visual>
      <origin xyz="0 0 0.02" rpy="0 0 0"/>
      <geometry>
        <mesh filename="..meshes/Link4.stl" scale="1 1 1"/>
      </geometry>
      <material name="gray">
        <color rgba="0.6 0.6 0.6 1"/>
      </material>
    </visual>
    <collision>
      <origin xyz="0 0 0.02" rpy="0 0 0"/>
      <geometry>
        <mesh filename="..meshes/Link4.stl" scale="1 1 1"/>
      </geometry>
    </collision>
    <inertial>
      <mass value="0.01"/>
      <inertia ixx="1e-5" ixy="0" ixz="0"
               iyy="1e-5" iyz="0"
               izz="1e-5"/>
    </inertial>
  </link>

  <!-- Link 6 (End Effector) -->
  <link name="link6">
    <inertial>
      <origin xyz="0 0 0" rpy="0 0 0"/>
      <mass value="0.1"/>
      <inertia ixx="0.00001" iyy="0.00001" izz="0.00001" ixy="0" ixz="0" iyz="0"/>
    </inertial>
    <visual>
      <origin xyz="0 0 0" rpy="0 0 0"/>
      <geometry>
        <mesh filename="../meshes/Link5.stl" scale="0.001 0.001 0.001"/>
      </geometry>
    </visual>
    <collision>
      <origin xyz="0 0 0" rpy="0 0 0"/>
      <geometry>
        <mesh filename="../meshes/Link5.stl" scale="0.001 0.001 0.001"/>
      </geometry>
    </collision>
  </link>

  <!-- Joints -->
  <joint name="joint1" type="revolute">
    <parent link="link1"/>
    <child link="link2"/>
    <origin xyz="0 0 0.0095" rpy="0 0 0"/>
    <axis xyz="0 0 1"/>
    <limit lower="-1.57" upper="1.57" effort="10" velocity="1"/>
  </joint>
  

  <joint name="joint2" type="revolute">
    <parent link="link2"/>
    <child link="link3"/>
    <origin xyz="0 -0.02 0.075" rpy="0 0 0"/>
    <axis xyz="1 0 0"/>
    <limit lower="-1.256" upper="3.14" effort="10" velocity="1"/>
  </joint>

  <joint name="joint3" type="revolute">
    <parent link="link3"/>
    <child link="link4"/>
    <origin xyz="0 0.058 0.162" rpy="0 0 0"/>
    <axis xyz="1 0 0"/>
    <limit lower="-3.14" upper="0.38" effort="10" velocity="1"/>
  </joint>

  <joint name="joint4" type="revolute">
    <parent link="link4"/>
    <child link="link5"/>
    <origin xyz="0 -0.21 -0.035" rpy="0 0 0"/>
    <axis xyz="1 0 0"/>
    <limit lower="-1.57" upper="1.57" effort="10" velocity="1"/>
  </joint>

  <joint name="joint5" type="revolute">
    <parent link="tool"/>
    <child link="link5"/>
    <origin xyz="0 0 0.02" rpy="0 0 0"/>
    <axis xyz="0 0 1"/>
    <limit lower="-1.57" upper="1.57" effort="1.0" velocity="1.0"/>
  </joint>

<!-- Tool Link (End Effector) -->
<link name="tool">
    <inertial>
      <origin xyz="0 0 0" rpy="0 0 0"/>
      <mass value="0.01"/>
      <inertia ixx="0.00001" iyy="0.00001" izz="0.00001" ixy="0" ixz="0" iyz="0"/>
    </inertial>
    <!-- <visual>
      <origin xyz="0 0 0" rpy="0 0 0"/>
      <geometry>
        <sphere radius="0.015"/>
      </geometry>
      <material name="tool_material">
        <color rgba="0.2 0.8 0.2 1"/>
      </material> -->
    <!-- </visual> -->
    <!-- <collision>
      <origin xyz="0 0 0" rpy="0 0 0"/>
      <geometry>
        <sphere radius="0.015"/>
      </geometry>
    </collision> -->
</link>

<!-- Tool Joint -->
<joint name="tool_joint" type="fixed">
    <parent link="link5"/>
    <child link="tool"/>
    <origin xyz="0.0 -0.035 -0.06" rpy="0 0 0"/>  <!-- Adjust this offset based on your suction cup length -->
</joint>


<!-- Camera Link -->
<link name="camera_link">
    <visual>
      <origin xyz="0 0 0" rpy="0 0 0"/>
      <geometry>
        <sphere radius="0.01"/>
      </geometry>
      <material name="camera_material">
        <color rgba="0.0 0.0 1.0 1"/>
      </material>
    </visual>
    <collision>
      <origin xyz="0 0 0" rpy="0 0 0"/>
      <geometry>
        <sphere radius="0.01"/>
      </geometry>
    </collision>
</link>

<!-- Camera Joint -->
<joint name="camera_joint" type="fixed">
    <parent link="tool"/>
    <child link="camera_link"/>
    <origin xyz="0.02 0 0.05" rpy="0 1.57 -1.57"/>  <!-- 180 degrees flip around X-axis -->
</joint>



</robot>